Workbook

Sheet Sales Data
A1: ID | B1: Category | C1: Cost | D1: Price | E1: Sold | F1: Status | G1: Margin
A2: 1 | B2: T-Shirt | C2: 200 | D2: 360 | E2: =TRUE() -> TRUE | F2: Sold | G2: =D2-C2 -> 160
A3: 2 | B3: T-Shirt | C3: 100 | D3: 390 | E3: =TRUE() -> TRUE | F3: Sold | G3: =D3-C3 -> 290
A4: 3 | B4: T-Shirt | C4: 130 | D4: 380 | E4: =TRUE() -> TRUE | F4: Sold | G4: =D4-C4 -> 250
A5: 4 | B5: T-Shirt | C5: 120 | D5: 360 | E5: =FALSE() -> FALSE | F5: Unsold | G5: =D5-C5 -> 240
A6: 5 | B6: T-Shirt | C6: 200 | D6: 430 | E6: =TRUE() -> TRUE | F6: Sold | G6: =D6-C6 -> 230
A7: 6 | B7: T-Shirt | C7: 110 | D7: 440 | E7: =FALSE() -> FALSE | F7: Unsold | G7: =D7-C7 -> 330
A8: 7 | B8: T-Shirt | C8: 160 | D8: 350 | E8: =TRUE() -> TRUE | F8: Sold | G8: =D8-C8 -> 190
A9: 8 | B9: T-Shirt | C9: 100 | D9: 360 | E9: =TRUE() -> TRUE | F9: Sold | G9: =D9-C9 -> 260
A10: 9 | B10: T-Shirt | C10: 130 | D10: 380 | E10: =FALSE() -> FALSE | F10: Unsold | G10: =D10-C10 -> 250
A11: 10 | B11: T-Shirt | C11: 180 | D11: 440 | E11: =TRUE() -> TRUE | F11: Sold | G11: =D11-C11 -> 260
A12: 11 | B12: T-Shirt | C12: 100 | D12: 430 | E12: =FALSE() -> FALSE | F12: Unsold | G12: =D12-C12 -> 330
A13: 12 | B13: T-Shirt | C13: 130 | D13: 450 | E13: =TRUE() -> TRUE | F13: Sold | G13: =D13-C13 -> 320
A14: 13 | B14: T-Shirt | C14: 180 | D14: 410 | E14: =TRUE() -> TRUE | F14: Sold | G14: =D14-C14 -> 230
A15: 14 | B15: T-Shirt | C15: 130 | D15: 420 | E15: =FALSE() -> FALSE | F15: Unsold | G15: =D15-C15 -> 290
A16: 15 | B16: T-Shirt | C16: 190 | D16: 390 | E16: =TRUE() -> TRUE | F16: Sold | G16: =D16-C16 -> 200
A17: 16 | B17: T-Shirt | C17: 100 | D17: 370 | E17: =TRUE() -> TRUE | F17: Sold | G17: =D17-C17 -> 270
A18: 17 | B18: T-Shirt | C18: 160 | D18: 400 | E18: =TRUE() -> TRUE | F18: Sold | G18: =D18-C18 -> 240
A19: 18 | B19: T-Shirt | C19: 140 | D19: 370 | E19: =TRUE() -> TRUE | F19: Sold | G19: =D19-C19 -> 230
A20: 19 | B20: T-Shirt | C20: 130 | D20: 400 | E20: =TRUE() -> TRUE | F20: Sold | G20: =D20-C20 -> 270
A21: 20 | B21: T-Shirt | C21: 110 | D21: 360 | E21: =TRUE() -> TRUE | F21: Sold | G21: =D21-C21 -> 250
A22: 21 | B22: T-Shirt | C22: 160 | D22: 360 | E22: =TRUE() -> TRUE | F22: Sold | G22: =D22-C22 -> 200
A23: 22 | B23: T-Shirt | C23: 150 | D23: 400 | E23: =TRUE() -> TRUE | F23: Sold | G23: =D23-C23 -> 250
A24: 23 | B24: T-Shirt | C24: 190 | D24: 390 | E24: =TRUE() -> TRUE | F24: Sold | G24: =D24-C24 -> 200
A25: 24 | B25: T-Shirt | C25: 100 | D25: 420 | E25: =TRUE() -> TRUE | F25: Sold | G25: =D25-C25 -> 320
A26: 25 | B26: T-Shirt | C26: 180 | D26: 360 | E26: =TRUE() -> TRUE | F26: Sold | G26: =D26-C26 -> 180
A27: 26 | B27: T-Shirt | C27: 160 | D27: 360 | E27: =TRUE() -> TRUE | F27: Sold | G27: =D27-C27 -> 200
... A30: 29 | B30: T-Shirt | C30: 150 | D30: 440 | E30: =TRUE() -> TRUE | F30: Sold | G30: =D30-C30 -> 290
A31: 30 | B31: T-Shirt | C31: 130 | D31: 360 | E31: =FALSE() -> FALSE | F31: Unsold | G31: =D31-C31 -> 230
A32: 31 | B32: T-Shirt | C32: 100 | D32: 450 | E32: =TRUE() -> TRUE | F32: Sold | G32: =D32-C32 -> 350
A33: 32 | B33: T-Shirt | C33: 130 | D33: 390 | E33: =TRUE() -> TRUE | F33: Sold | G33: =D33-C33 -> 260
A34: 33 | B34: T-Shirt | C34: 110 | D34: 380 | E34: =TRUE() -> TRUE | F34: Sold | G34: =D34-C34 -> 270
A35: 34 | B35: T-Shirt | C35: 110 | D35: 410 | E35: =FALSE() -> FALSE | F35: Unsold | G35: =D35-C35 -> 300
A36: 35 | B36: T-Shirt | C36: 140 | D36: 420 | E36: =TRUE() -> TRUE | F36: Sold | G36: =D36-C36 -> 280
A37: 36 | B37: T-Shirt | C37: 200 | D37: 400 | E37: =TRUE() -> TRUE | F37: Sold | G37: =D37-C37 -> 200
A38: 37 | B38: T-Shirt | C38: 120 | D38: 400 | E38: =TRUE() -> TRUE | F38: Sold | G38: =D38-C38 -> 280
A39: 38 | B39: T-Shirt | C39: 150 | D39: 380 | E39: =TRUE() -> TRUE | F39: Sold | G39: =D39-C39 -> 230
A40: 39 | B40: T-Shirt | C40: 200 | D40: 390 | E40: =TRUE() -> TRUE | F40: Sold | G40: =D40-C40 -> 190
A41: 40 | B41: T-Shirt | C41: 200 | D41: 450 | E41: =TRUE() -> TRUE | F41: Sold | G41: =D41-C41 -> 250
A42: 41 | B42: T-Shirt | C42: 110 | D42: 440 | E42: =FALSE() -> FALSE | F42: Unsold | G42: =D42-C42 -> 330
...

Sheet Summary
A1: Drippy But Broke — Sprint Summary
A3: Metric | B3: Value
A4: Total pieces sourced | B4: =COUNTA('Sales Data'!A2:A101) -> 100
A5: Pieces sold | B5: =COUNTIF('Sales Data'!F2:F101,"Sold") -> 80
A6: Pieces unsold | B6: =COUNTIF('Sales Data'!F2:F101,"Unsold") -> 20
A7: Sell-through rate | B7: =B5/B4 -> 0.8
A8: Total sourcing cost | B8: =SUM('Sales Data'!C2:C101) -> 17840
A9: Total revenue (sold only) | B9: =SUMIF('Sales Data'!F2:F101,"Sold",'Sales Data'!D2:D101) -> 37570
A10: Net profit | B10: =B9-B8 -> 19730
A11: Return on cost | B11: =B10/B8 -> 1.1059417
A12: Average selling price (all stock) | B12: =AVERAGE('Sales Data'!D2:D101) -> 473.6
A13: Breakeven units (cost / avg price) | B13: =B8/B12 -> 37.668919
A14: Unsold stock value (at cost) | B14: =SUMIF('Sales Data'!F2:F101,"Unsold",'Sales Data'!C2:C101) -> 3450
A16: Formulas reference the Sales Data sheet directly — recalculates if you edit costs/prices/sold status there.

Sheet Category Breakdown
A1: Metric | B1: T-Shirt | C1: Shirt | D1: Total
A2: Units sourced | B2: =COUNTIF('Sales Data'!$B$2:$B$101,$B$1) -> 60 | C2: =COUNTIF('Sales Data'!$B$2:$B$101,$C$1) -> 40 | D2: =B2+C2 -> 100
A3: Units sold | B3: =COUNTIFS('Sales Data'!$B$2:$B$101,$B$1,'Sales Data'!$F$2:$F$101,"Sold") -> 48 | C3: =COUNTIFS('Sales Data'!$B$2:$B$101,$C$1,'Sales Data'!$F$2:$F$101,"Sold") -> 32 | D3: =B3+C3 -> 80
A4: Units unsold | B4: =COUNTIFS('Sales Data'!$B$2:$B$101,$B$1,'Sales Data'!$F$2:$F$101,"Unsold") -> 12 | C4: =COUNTIFS('Sales Data'!$B$2:$B$101,$C$1,'Sales Data'!$F$2:$F$101,"Unsold") -> 8 | D4: =B4+C4 -> 20
A5: Cost | B5: =SUMIF('Sales Data'!$B$2:$B$101,$B$1,'Sales Data'!$C$2:$C$101) -> 8980 | C5: =SUMIF('Sales Data'!$B$2:$B$101,$C$1,'Sales Data'!$C$2:$C$101) -> 8860 | D5: =B5+C5 -> 17840
A6: Revenue | B6: =SUMIFS('Sales Data'!$D$2:$D$101,'Sales Data'!$B$2:$B$101,$B$1,'Sales Data'!$F$2:$F$101,"Sold") -> 19080 | C6: =SUMIFS('Sales Data'!$D$2:$D$101,'Sales Data'!$B$2:$B$101,$C$1,'Sales Data'!$F$2:$F$101,"Sold") -> 18490 | D6: =B6+C6 -> 37570
A7: Profit | B7: =B6-B5 -> 10100 | C7: =C6-C5 -> 9630 | D7: =B7+C7 -> 19730
A8: Avg selling price | B8: =AVERAGEIF('Sales Data'!$B$2:$B$101,$B$1,'Sales Data'!$D$2:$D$101) -> 398.16667 | C8: =AVERAGEIF('Sales Data'!$B$2:$B$101,$C$1,'Sales Data'!$D$2:$D$101) -> 586.75 | D8: =Summary!B12 -> 473.6
A9: Breakeven units | B9: =B5/B8 -> 22.55337 | C9: =C5/C8 -> 15.100128 | D9: =Summary!B13 -> 37.668919
